TC-1						| Delete an existing instance of Customer
preconditions				| []
Input						| [
							idCustomer: 123e4567-e89b-12d3-a456-426614174000 ]
Steps						| [
							Inform {idCustomer=123e4567-e89b-12d3-a456-426614174000}, 
							Mock existsByIdCustomer in CustomerRepository to return true, 
							Mock deleteById method in CustomerRepository, returning void, 
							Call method execute(idCustomer) in DeleteCustomerUseCase class. This is a void method, 
							Verify mock deleteById method in CustomerRepository was called, 
							Verify that existsByIdCustomer in CustomerRepository was called]
Expected Result				| Delete an existing instance of Customer

TC-2						| deleteCustomerUseCase.execute(idCustomer) does not find the instance of Customer. CustomerException is thrown
preconditions				| [The repository must have no instance and It must return false]
Input						| [
							idCustomer: 123e4567-e89b-12d3-a456-426614174000 ]
Steps						| [
							Inform {idCustomer=123e4567-e89b-12d3-a456-426614174000}, 
							Mock existsByIdCustomer in CustomerRepository to return false, 
							Call method execute(idCustomer) in DeleteCustomerUseCase, 
							Verify that CustomerException is thrown with the following error message: Customer not found, 
							Verify mock deleteById method in CustomerRepository was not called, 
							Verify that existsByIdCustomer in CustomerRepository was called]
Expected Result				| deleteCustomerUseCase.execute(idCustomer) does not find the instance of Customer. CustomerException is thrown

TC-3						| DataBaseException is thrown
preconditions				| []
Input						| [
							idCustomer: 123e4567-e89b-12d3-a456-426614174000 ]
Steps						| [
							Inform {idCustomer=123e4567-e89b-12d3-a456-426614174000}, 
							Mock existsByIdCustomer method in CustomerRepository to return org.springframework.dao.DataIntegrityViolationException, 
							Call method execute(idCustomer) in DeleteCustomerUseCase, 
							Verify that DataBaseException is thrown, 
							Verify mocks]
Expected Result				| DataBaseException is thrown


